2020-05-26 13:33:23,905 INFO: Askwall startup [in C:\Users\HP\Desktop\AskWall\app\__init__.py:46]
2020-05-26 13:40:06,854 INFO: Askwall startup [in C:\Users\HP\Desktop\AskWall\app\__init__.py:46]
2020-05-26 14:07:56,853 INFO: Askwall startup [in C:\Users\HP\Desktop\AskWall\app\__init__.py:46]
2020-05-26 14:08:15,733 INFO: Askwall startup [in C:\Users\HP\Desktop\AskWall\app\__init__.py:46]
2020-05-26 14:08:25,883 INFO: Askwall startup [in C:\Users\HP\Desktop\AskWall\app\__init__.py:46]
2020-05-26 14:09:25,403 INFO: Askwall startup [in C:\Users\HP\Desktop\AskWall\app\__init__.py:46]
2020-05-26 15:01:08,846 INFO: Askwall startup [in C:\Users\HP\Desktop\AskWall\app\__init__.py:46]
2020-05-26 15:01:41,056 INFO: Askwall startup [in C:\Users\HP\Desktop\AskWall\app\__init__.py:46]
2020-05-26 16:34:19,578 INFO: Askwall startup [in C:\Users\HP\Desktop\AskWall\app\__init__.py:46]
2020-05-26 16:34:28,067 INFO: Askwall startup [in C:\Users\HP\Desktop\AskWall\app\__init__.py:46]
2020-05-26 16:37:29,748 INFO: Askwall startup [in C:\Users\HP\Desktop\AskWall\app\__init__.py:46]
2020-05-26 16:41:12,927 INFO: Askwall startup [in C:\Users\HP\Desktop\AskWall\app\__init__.py:46]
2020-05-26 16:45:49,997 INFO: Askwall startup [in C:\Users\HP\Desktop\AskWall\app\__init__.py:46]
2020-05-26 16:50:58,522 INFO: Askwall startup [in C:\Users\HP\Desktop\AskWall\app\__init__.py:46]
2020-05-26 16:51:59,784 INFO: Askwall startup [in C:\Users\HP\Desktop\AskWall\app\__init__.py:46]
2020-05-26 16:54:46,037 INFO: Askwall startup [in C:\Users\HP\Desktop\AskWall\app\__init__.py:46]
2020-05-26 16:55:56,007 INFO: Askwall startup [in C:\Users\HP\Desktop\AskWall\app\__init__.py:46]
2020-05-26 16:56:04,827 ERROR: Exception on /unfollow/sagard [GET] [in C:\Users\HP\anaconda3\envs\askwall\lib\site-packages\flask\app.py:1892]
Traceback (most recent call last):
  File "C:\Users\HP\anaconda3\envs\askwall\lib\site-packages\flask\app.py", line 2447, in wsgi_app
    response = self.full_dispatch_request()
  File "C:\Users\HP\anaconda3\envs\askwall\lib\site-packages\flask\app.py", line 1952, in full_dispatch_request
    rv = self.handle_user_exception(e)
  File "C:\Users\HP\anaconda3\envs\askwall\lib\site-packages\flask\app.py", line 1821, in handle_user_exception
    reraise(exc_type, exc_value, tb)
  File "C:\Users\HP\anaconda3\envs\askwall\lib\site-packages\flask\_compat.py", line 39, in reraise
    raise value
  File "C:\Users\HP\anaconda3\envs\askwall\lib\site-packages\flask\app.py", line 1950, in full_dispatch_request
    rv = self.dispatch_request()
  File "C:\Users\HP\anaconda3\envs\askwall\lib\site-packages\flask\app.py", line 1936, in dispatch_request
    return self.view_functions[rule.endpoint](**req.view_args)
  File "C:\Users\HP\anaconda3\envs\askwall\lib\site-packages\flask_login\utils.py", line 261, in decorated_view
    return func(*args, **kwargs)
  File "C:\Users\HP\Desktop\AskWall\app\routes.py", line 129, in unfollow
    db.session.commit()
  File "C:\Users\HP\anaconda3\envs\askwall\lib\site-packages\sqlalchemy\orm\scoping.py", line 162, in do
    return getattr(self.registry(), name)(*args, **kwargs)
  File "C:\Users\HP\anaconda3\envs\askwall\lib\site-packages\sqlalchemy\orm\session.py", line 1036, in commit
    self.transaction.commit()
  File "C:\Users\HP\anaconda3\envs\askwall\lib\site-packages\sqlalchemy\orm\session.py", line 503, in commit
    self._prepare_impl()
  File "C:\Users\HP\anaconda3\envs\askwall\lib\site-packages\sqlalchemy\orm\session.py", line 482, in _prepare_impl
    self.session.flush()
  File "C:\Users\HP\anaconda3\envs\askwall\lib\site-packages\sqlalchemy\orm\session.py", line 2496, in flush
    self._flush(objects)
  File "C:\Users\HP\anaconda3\envs\askwall\lib\site-packages\sqlalchemy\orm\session.py", line 2637, in _flush
    transaction.rollback(_capture_exception=True)
  File "C:\Users\HP\anaconda3\envs\askwall\lib\site-packages\sqlalchemy\util\langhelpers.py", line 69, in __exit__
    exc_value, with_traceback=exc_tb,
  File "C:\Users\HP\anaconda3\envs\askwall\lib\site-packages\sqlalchemy\util\compat.py", line 178, in raise_
    raise exception
  File "C:\Users\HP\anaconda3\envs\askwall\lib\site-packages\sqlalchemy\orm\session.py", line 2597, in _flush
    flush_context.execute()
  File "C:\Users\HP\anaconda3\envs\askwall\lib\site-packages\sqlalchemy\orm\unitofwork.py", line 422, in execute
    rec.execute(self)
  File "C:\Users\HP\anaconda3\envs\askwall\lib\site-packages\sqlalchemy\orm\unitofwork.py", line 540, in execute
    self.dependency_processor.process_saves(uow, states)
  File "C:\Users\HP\anaconda3\envs\askwall\lib\site-packages\sqlalchemy\orm\dependency.py", line 1177, in process_saves
    uowcommit, secondary_insert, secondary_update, secondary_delete
  File "C:\Users\HP\anaconda3\envs\askwall\lib\site-packages\sqlalchemy\orm\dependency.py", line 1207, in _run_crud
    result.rowcount,
sqlalchemy.orm.exc.StaleDataError: DELETE statement on table 'followers' expected to delete 1 row(s); Only 30 were matched.
